<sdf version='1.7'>
  <world name='default'>
    <light name='sun' type='directional'>
      <cast_shadows>1</cast_shadows>
      <pose>0 0 10 0 -0 0</pose>
      <diffuse>0.8 0.8 0.8 1</diffuse>
      <specular>0.2 0.2 0.2 1</specular>
      <attenuation>
        <range>1000</range>
        <constant>0.9</constant>
        <linear>0.01</linear>
        <quadratic>0.001</quadratic>
      </attenuation>
      <direction>-0.5 0.1 -0.9</direction>
      <spot>
        <inner_angle>0</inner_angle>
        <outer_angle>0</outer_angle>
        <falloff>0</falloff>
      </spot>
    </light>
    <model name='ground_plane'>
      <static>1</static>
      <link name='link'>
        <collision name='collision'>
          <geometry>
            <plane>
              <normal>0 0 1</normal>
              <size>100 100</size>
            </plane>
          </geometry>
          <surface>
            <contact>
              <collide_bitmask>65535</collide_bitmask>
              <ode/>
            </contact>
            <friction>
              <ode>
                <mu>100</mu>
                <mu2>50</mu2>
              </ode>
              <torsional>
                <ode/>
              </torsional>
            </friction>
            <bounce/>
          </surface>
          <max_contacts>10</max_contacts>
        </collision>
        <visual name='visual'>
          <cast_shadows>0</cast_shadows>
          <geometry>
            <plane>
              <normal>0 0 1</normal>
              <size>100 100</size>
            </plane>
          </geometry>
          <material>
            <script>
              <uri>file://media/materials/scripts/gazebo.material</uri>
              <name>Gazebo/Grey</name>
            </script>
          </material>
        </visual>
        <self_collide>0</self_collide>
        <enable_wind>0</enable_wind>
        <kinematic>0</kinematic>
      </link>
    </model>
    <gravity>0 0 -9.8</gravity>
    <magnetic_field>6e-06 2.3e-05 -4.2e-05</magnetic_field>
    <atmosphere type='adiabatic'/>
    <physics type='ode'>
      <max_step_size>0.001</max_step_size>
      <real_time_factor>1</real_time_factor>
      <real_time_update_rate>1000</real_time_update_rate>
    </physics>
    <scene>
      <ambient>0.4 0.4 0.4 1</ambient>
      <background>0.7 0.7 0.7 1</background>
      <shadows>1</shadows>
    </scene>
    <wind/>
    <spherical_coordinates>
      <surface_model>EARTH_WGS84</surface_model>
      <latitude_deg>0</latitude_deg>
      <longitude_deg>0</longitude_deg>
      <elevation>0</elevation>
      <heading_deg>0</heading_deg>
    </spherical_coordinates>
    <state world_name='default'>
      <sim_time>9 232000000</sim_time>
      <real_time>16 619664014</real_time>
      <wall_time>1692197634 237956129</wall_time>
      <iterations>9232</iterations>
      <model name='Gas_Station'>
        <pose>0.209351 0.670195 0 0 -0 0</pose>
        <scale>1 1 1</scale>
        <link name='link'>
          <pose>0.209351 0.670195 0 0 -0 0</pose>
          <velocity>0 0 0 0 -0 0</velocity>
          <acceleration>0 0 0 0 -0 0</acceleration>
          <wrench>0 0 0 0 -0 0</wrench>
        </link>
      </model>
      <model name='ground_plane'>
        <pose>0 0 0 0 -0 0</pose>
        <scale>1 1 1</scale>
        <link name='link'>
          <pose>0 0 0 0 -0 0</pose>
          <velocity>0 0 0 0 -0 0</velocity>
          <acceleration>0 0 0 0 -0 0</acceleration>
          <wrench>0 0 0 0 -0 0</wrench>
        </link>
      </model>
      <model name='marvin_description'>
        <pose>-0.005964 0.00038 0.058614 9e-05 -0.000111 -0.020312</pose>
        <scale>1 1 1</scale>
        <link name='back_wheel_left'>
          <pose>-0.132509 0.086957 0.031464 8.4e-05 -0.001118 -0.02031</pose>
          <velocity>3.8e-05 -0.000202 0.008534 0.006397 0.001698 0.000837</velocity>
          <acceleration>-0.111268 -0.317032 17.0672 2.34061 0.839309 -2.01667</acceleration>
          <wrench>-0.004289 -0.012219 0.657821 0 -0 0</wrench>
        </link>
        <link name='back_wheel_right'>
          <pose>-0.135879 -0.078965 0.031455 4.1e-05 -0.088066 -0.020318</pose>
          <velocity>0.00015 0.000258 0.009038 -0.0082 0.004775 1.4e-05</velocity>
          <acceleration>0.120617 0.170547 18.3223 2.60643 -0.570465 -0.35989</acceleration>
          <wrench>0.004649 0.006573 0.706197 0 -0 0</wrench>
        </link>
        <link name='base_link'>
          <pose>-0.005964 0.00038 0.058614 9e-05 -0.000111 -0.020312</pose>
          <velocity>0.000155 1.7e-05 0.008381 0.002919 0.001657 0.001264</velocity>
          <acceleration>0.193819 -0.220112 17.4407 1.58497 0.925679 -2.22634</acceleration>
          <wrench>0.226648 -0.257395 20.3948 0 -0 0</wrench>
        </link>
        <link name='front_wheel_left'>
          <pose>0.126438 0.081705 0.037137 1e-05 0.020344 -0.020314</pose>
          <velocity>8.8e-05 0.000784 0.008693 -0.021101 0.002383 2.1e-05</velocity>
          <acceleration>-0.002538 1.01232 18.1855 1.2653 -0.411017 2.88689</acceleration>
          <wrench>-0.00016 0.063953 1.14885 0 -0 0</wrench>
        </link>
        <link name='front_wheel_right'>
          <pose>0.123067 -0.084232 0.037122 9e-05 8.3e-05 -0.020312</pose>
          <velocity>0.00013 0.000185 0.007801 0.003829 0.001856 0.000279</velocity>
          <acceleration>0.092604 0.163071 16.7168 2.2207 0.729585 -2.69259</acceleration>
          <wrench>0.00585 0.010302 1.05606 0 -0 0</wrench>
        </link>
      </model>
      <light name='sun'>
        <pose>0 0 10 0 -0 0</pose>
      </light>
    </state>
    <gui fullscreen='0'>
      <camera name='user_camera'>
        <pose>-1.45378 1.97747 1.61591 0 0.403344 -0.719845</pose>
        <view_controller>orbit</view_controller>
        <projection_type>perspective</projection_type>
      </camera>
    </gui>
    <model name='marvin_description'>
      <link name='base_link'>
        <inertial>
          <pose>0.002165 0.000311 0.047127 0 -0 0</pose>
          <mass>1.16938</mass>
          <inertia>
            <ixx>0.00507793</ixx>
            <ixy>2.36821e-06</ixy>
            <ixz>-0.00228687</ixz>
            <iyy>0.00762745</iyy>
            <iyz>1.14767e-05</iyz>
            <izz>0.0040493</izz>
          </inertia>
        </inertial>
        <collision name='base_link_collision'>
          <pose>0 0 0 0 -0 0</pose>
          <geometry>
            <mesh>
              <scale>1 1 1</scale>
              <uri>model://marvin_description/meshes/base_link.STL</uri>
            </mesh>
          </geometry>
          <surface>
            <contact>
              <ode>
                <kp>1e+06</kp>
                <kd>1</kd>
              </ode>
            </contact>
            <friction>
              <ode>
                <mu>200</mu>
                <mu2>200</mu2>
              </ode>
              <torsional>
                <ode/>
              </torsional>
            </friction>
            <bounce/>
          </surface>
          <max_contacts>10</max_contacts>
        </collision>
        <collision name='base_link_fixed_joint_lump__camera_depth_collision_1'>
          <pose>0.055 0 0.09 0 -0 0</pose>
          <geometry>
            <mesh>
              <scale>1 1 1</scale>
              <uri>model://marvin_description/meshes/depth_camera.STL</uri>
            </mesh>
          </geometry>
          <surface>
            <contact>
              <ode/>
            </contact>
            <friction>
              <ode/>
              <torsional>
                <ode/>
              </torsional>
            </friction>
            <bounce/>
          </surface>
          <max_contacts>10</max_contacts>
        </collision>
        <collision name='base_link_fixed_joint_lump__camera_left_collision_2'>
          <pose>-0.005 0.047832 0.095 0 -0 1.5708</pose>
          <geometry>
            <mesh>
              <scale>1 1 1</scale>
              <uri>model://marvin_description/meshes/camera_left.STL</uri>
            </mesh>
          </geometry>
          <surface>
            <contact>
              <ode/>
            </contact>
            <friction>
              <ode/>
              <torsional>
                <ode/>
              </torsional>
            </friction>
            <bounce/>
          </surface>
          <max_contacts>10</max_contacts>
        </collision>
        <collision name='base_link_fixed_joint_lump__camera_right_collision_3'>
          <pose>-0.005 -0.047832 0.095 0 0 -1.5708</pose>
          <geometry>
            <mesh>
              <scale>1 1 1</scale>
              <uri>model://marvin_description/meshes/camera_right.STL</uri>
            </mesh>
          </geometry>
          <surface>
            <contact>
              <ode/>
            </contact>
            <friction>
              <ode/>
              <torsional>
                <ode/>
              </torsional>
            </friction>
            <bounce/>
          </surface>
          <max_contacts>10</max_contacts>
        </collision>
        <collision name='base_link_fixed_joint_lump__front_handle_left_collision_4'>
          <pose>0.13072 0.057509 -0.010582 0 -0 0</pose>
          <geometry>
            <mesh>
              <scale>1 1 1</scale>
              <uri>model://marvin_description/meshes/front_handle_left.STL</uri>
            </mesh>
          </geometry>
          <surface>
            <contact>
              <ode>
                <kp>1e+06</kp>
                <kd>1</kd>
              </ode>
            </contact>
            <friction>
              <ode>
                <mu>0.1</mu>
                <mu2>0.1</mu2>
              </ode>
              <torsional>
                <ode/>
              </torsional>
            </friction>
            <bounce/>
          </surface>
          <max_contacts>10</max_contacts>
        </collision>
        <collision name='base_link_fixed_joint_lump__front_handle_right_collision_5'>
          <pose>0.13072 -0.055491 -0.010582 0 -0 0</pose>
          <geometry>
            <mesh>
              <scale>1 1 1</scale>
              <uri>model://marvin_description/meshes/front_handle_right.STL</uri>
            </mesh>
          </geometry>
          <surface>
            <contact>
              <ode>
                <kp>1e+06</kp>
                <kd>1</kd>
              </ode>
            </contact>
            <friction>
              <ode>
                <mu>0.1</mu>
                <mu2>0.1</mu2>
              </ode>
              <torsional>
                <ode/>
              </torsional>
            </friction>
            <bounce/>
          </surface>
          <max_contacts>10</max_contacts>
        </collision>
        <collision name='base_link_fixed_joint_lump__lidar_collision_6'>
          <pose>0 0 0.14 0 -0 0</pose>
          <geometry>
            <mesh>
              <scale>1 1 1</scale>
              <uri>model://marvin_description/meshes/lidar.STL</uri>
            </mesh>
          </geometry>
          <surface>
            <contact>
              <ode/>
            </contact>
            <friction>
              <ode/>
              <torsional>
                <ode/>
              </torsional>
            </friction>
            <bounce/>
          </surface>
          <max_contacts>10</max_contacts>
        </collision>
        <visual name='base_link_visual'>
          <pose>0 0 0 0 -0 0</pose>
          <geometry>
            <mesh>
              <scale>1 1 1</scale>
              <uri>model://marvin_description/meshes/base_link.STL</uri>
            </mesh>
          </geometry>
          <material>
            <script>
              <name>Gazebo/Black</name>
              <uri>file://media/materials/scripts/gazebo.material</uri>
            </script>
          </material>
        </visual>
        <visual name='base_link_fixed_joint_lump__camera_depth_visual_1'>
          <pose>0.055 0 0.09 0 -0 0</pose>
          <geometry>
            <mesh>
              <scale>1 1 1</scale>
              <uri>model://marvin_description/meshes/depth_camera.STL</uri>
            </mesh>
          </geometry>
          <material>
            <ambient>0.416 0.051 0.047 1</ambient>
            <diffuse>0.416 0.051 0.047 1</diffuse>
            <specular>0.416 0.051 0.047 1</specular>
            <emissive>0.416 0.051 0.047 1</emissive>
          </material>
        </visual>
        <visual name='base_link_fixed_joint_lump__camera_left_visual_2'>
          <pose>-0.005 0.047832 0.095 0 -0 0</pose>
          <geometry>
            <mesh>
              <scale>1 1 1</scale>
              <uri>model://marvin_description/meshes/camera_left.STL</uri>
            </mesh>
          </geometry>
        </visual>
        <visual name='base_link_fixed_joint_lump__camera_right_visual_3'>
          <pose>-0.005 -0.047832 0.095 0 -0 0</pose>
          <geometry>
            <mesh>
              <scale>1 1 1</scale>
              <uri>model://marvin_description/meshes/camera_right.STL</uri>
            </mesh>
          </geometry>
        </visual>
        <visual name='base_link_fixed_joint_lump__front_handle_left_visual_4'>
          <pose>0.13072 0.057509 -0.010582 0 -0 0</pose>
          <geometry>
            <mesh>
              <scale>1 1 1</scale>
              <uri>model://marvin_description/meshes/front_handle_left.STL</uri>
            </mesh>
          </geometry>
          <material>
            <script>
              <name>Gazebo/White</name>
              <uri>file://media/materials/scripts/gazebo.material</uri>
            </script>
          </material>
        </visual>
        <visual name='base_link_fixed_joint_lump__front_handle_right_visual_5'>
          <pose>0.13072 -0.055491 -0.010582 0 -0 0</pose>
          <geometry>
            <mesh>
              <scale>1 1 1</scale>
              <uri>model://marvin_description/meshes/front_handle_right.STL</uri>
            </mesh>
          </geometry>
          <material>
            <script>
              <name>Gazebo/White</name>
              <uri>file://media/materials/scripts/gazebo.material</uri>
            </script>
          </material>
        </visual>
        <visual name='base_link_fixed_joint_lump__lidar_visual_6'>
          <pose>0 0 0.14 0 -0 0</pose>
          <geometry>
            <mesh>
              <scale>1 1 1</scale>
              <uri>model://marvin_description/meshes/lidar.STL</uri>
            </mesh>
          </geometry>
          <material>
            <ambient>0.003 0.639 0.223 1</ambient>
            <diffuse>0.003 0.639 0.223 1</diffuse>
            <specular>0.003 0.639 0.223 1</specular>
            <emissive>0 0 0 0</emissive>
          </material>
        </visual>
        <gravity>1</gravity>
        <sensor name='imu_sensor' type='imu'>
          <always_on>1</always_on>
          <update_rate>20</update_rate>
          <visualize>1</visualize>
          <topic>__default_topic__</topic>
          <plugin name='imu_plugin' filename='libgazebo_ros_imu_sensor.so'>
            <ros>
              <remapping>~/out:=imu/data</remapping>
            </ros>
            <topicName>imu/data</topicName>
            <bodyName>imu_link</bodyName>
            <updateRateHZ>10.0</updateRateHZ>
            <gaussianNoise>0.0</gaussianNoise>
            <xyzOffset>0 0 0</xyzOffset>
            <rpyOffset>0 0 0</rpyOffset>
            <frameName>imu_link</frameName>
            <initialOrientationAsReference>0</initialOrientationAsReference>
          </plugin>
          <pose>0 0 0 0 -0 0</pose>
          <imu/>
        </sensor>
        <sensor name='camera' type='depth'>
          <always_on>1</always_on>
          <update_rate>30</update_rate>
          <camera name='camera_depth'>
            <horizontal_fov>1.50098</horizontal_fov>
            <image>
              <width>640</width>
              <height>480</height>
              <format>R8G8B8</format>
            </image>
            <clip>
              <near>0.1</near>
              <far>100</far>
            </clip>
          </camera>
          <plugin name='camera_controller_depth' filename='libgazebo_ros_camera.so'>
            <ros>
              <remapping>/camera/camera_info:=/camera/color/camera_info</remapping>
              <remapping>/camera/image_raw:=/camera/color/image_raw</remapping>
              <remapping>/camera/points:=/camera/depth/color/points</remapping>
              <remapping>/camera/depth/image_raw:=/camera/depth/image_rect_raw</remapping>
            </ros>
            <min_depth>0.015</min_depth>
            <max_depth>3.0</max_depth>
            <hack_baseline>0.07</hack_baseline>
            <frame_name>camera_depth_optical</frame_name>
            <distortion_k1>0.00000001</distortion_k1>
            <distortion_k2>0.00000001</distortion_k2>
            <distortion_k3>0.00000001</distortion_k3>
            <distortion_t1>0.00000001</distortion_t1>
            <distortion_t2>0.00000001</distortion_t2>
          </plugin>
          <pose>0.055 0 0.09 0 -0 0</pose>
        </sensor>
        <sensor name='camera_left' type='camera'>
          <visualize>0</visualize>
          <update_rate>10</update_rate>
          <camera>
            <horizontal_fov>1.089</horizontal_fov>
            <image>
              <width>640</width>
              <height>480</height>
              <format>R8G8B8</format>
            </image>
            <clip>
              <near>0.05</near>
              <far>8</far>
            </clip>
          </camera>
          <plugin name='camera_controller_left' filename='libgazebo_ros_camera.so'>
            <frame_name>camera_optical_left</frame_name>
          </plugin>
          <pose>-0.005 0.047832 0.095 0 -0 1.5708</pose>
        </sensor>
        <sensor name='camera_right' type='camera'>
          <visualize>0</visualize>
          <update_rate>10</update_rate>
          <camera>
            <horizontal_fov>1.089</horizontal_fov>
            <image>
              <width>640</width>
              <height>480</height>
              <format>R8G8B8</format>
            </image>
            <clip>
              <near>0.05</near>
              <far>8</far>
            </clip>
          </camera>
          <plugin name='camera_controller_right' filename='libgazebo_ros_camera.so'>
            <frame_name>camera_optical_right</frame_name>
          </plugin>
          <pose>-0.005 -0.047832 0.095 0 0 -1.5708</pose>
        </sensor>
        <sensor name='lidar_head_hokuyo_sensor' type='ray'>
          <always_on>1</always_on>
          <update_rate>10</update_rate>
          <visualize>0</visualize>
          <ray>
            <scan>
              <horizontal>
                <samples>360</samples>
                <resolution>1</resolution>
                <min_angle>-3.1416</min_angle>
                <max_angle>3.1416</max_angle>
              </horizontal>
              <vertical>
                <samples>1</samples>
                <min_angle>0</min_angle>
                <max_angle>0</max_angle>
              </vertical>
            </scan>
            <range>
              <min>0.21</min>
              <max>5.5</max>
              <resolution>0.01</resolution>
            </range>
          </ray>
          <plugin name='lidar_gazebo_ros_head_hokuyo_controller' filename='libgazebo_ros_ray_sensor.so'>
            <ros>
              <remapping>~/out:=scan</remapping>
            </ros>
            <output_type>sensor_msgs/LaserScan</output_type>
            <alwaysOn>1</alwaysOn>
            <updateRate>10</updateRate>
            <frame_name>lidar</frame_name>
            <output_type>sensor_msgs/LaserScan</output_type>
          </plugin>
          <pose>0 0 0.14 0 -0 0</pose>
        </sensor>
        <self_collide>0</self_collide>
        <enable_wind>0</enable_wind>
        <kinematic>0</kinematic>
      </link>
      <joint name='joint_back_wheel_left' type='revolute'>
        <pose relative_to='base_link'>-0.12828 0.083987 -0.02714 0 -0 0</pose>
        <parent>base_link</parent>
        <child>back_wheel_left</child>
        <axis>
          <xyz>0 1 0</xyz>
          <limit>
            <effort>100</effort>
            <velocity>100</velocity>
            <lower>-1e+16</lower>
            <upper>1e+16</upper>
          </limit>
          <dynamics>
            <damping>0</damping>
            <friction>0.1</friction>
            <spring_reference>0</spring_reference>
            <spring_stiffness>0</spring_stiffness>
          </dynamics>
        </axis>
      </joint>
      <link name='back_wheel_left'>
        <pose relative_to='joint_back_wheel_left'>0 0 0 0 -0 0</pose>
        <inertial>
          <pose>0 -0.005556 0 0 -0 0</pose>
          <mass>0.038543</mass>
          <inertia>
            <ixx>1.5832e-05</ixx>
            <ixy>-1.9172e-21</ixy>
            <ixz>2.1838e-21</ixz>
            <iyy>2.7611e-05</iyy>
            <iyz>-7.8379e-11</iyz>
            <izz>1.5832e-05</izz>
          </inertia>
        </inertial>
        <collision name='back_wheel_left_collision'>
          <pose>0 0 0 0 -0 0</pose>
          <geometry>
            <mesh>
              <scale>1 1 1</scale>
              <uri>model://marvin_description/meshes/back_wheel_left.STL</uri>
            </mesh>
          </geometry>
          <surface>
            <contact>
              <ode>
                <kp>1e+06</kp>
                <kd>1</kd>
              </ode>
            </contact>
            <friction>
              <ode>
                <mu>200</mu>
                <mu2>200</mu2>
              </ode>
              <torsional>
                <ode/>
              </torsional>
            </friction>
            <bounce/>
          </surface>
          <max_contacts>10</max_contacts>
        </collision>
        <visual name='back_wheel_left_visual'>
          <pose>0 0 0 0 -0 0</pose>
          <geometry>
            <mesh>
              <scale>1 1 1</scale>
              <uri>model://marvin_description/meshes/back_wheel_left.STL</uri>
            </mesh>
          </geometry>
          <material>
            <script>
              <name>Gazebo/Red</name>
              <uri>file://media/materials/scripts/gazebo.material</uri>
            </script>
          </material>
        </visual>
        <self_collide>0</self_collide>
        <enable_wind>0</enable_wind>
        <kinematic>0</kinematic>
      </link>
      <joint name='joint_back_wheel_right' type='revolute'>
        <pose relative_to='base_link'>-0.12828 -0.08197 -0.02714 0 -0 0</pose>
        <parent>base_link</parent>
        <child>back_wheel_right</child>
        <axis>
          <xyz>0 1 0</xyz>
          <limit>
            <effort>100</effort>
            <velocity>100</velocity>
            <lower>-1e+16</lower>
            <upper>1e+16</upper>
          </limit>
          <dynamics>
            <damping>0</damping>
            <friction>0.1</friction>
            <spring_reference>0</spring_reference>
            <spring_stiffness>0</spring_stiffness>
          </dynamics>
        </axis>
      </joint>
      <link name='back_wheel_right'>
        <pose relative_to='joint_back_wheel_right'>0 0 0 0 -0 0</pose>
        <inertial>
          <pose>0 0.005556 0 0 -0 0</pose>
          <mass>0.038543</mass>
          <inertia>
            <ixx>1.5832e-05</ixx>
            <ixy>-5.5769e-21</ixy>
            <ixz>1.8661e-21</ixz>
            <iyy>2.7611e-05</iyy>
            <iyz>7.7791e-11</iyz>
            <izz>1.5832e-05</izz>
          </inertia>
        </inertial>
        <collision name='back_wheel_right_collision'>
          <pose>0 0 0 0 -0 0</pose>
          <geometry>
            <mesh>
              <scale>1 1 1</scale>
              <uri>model://marvin_description/meshes/back_wheel_right.STL</uri>
            </mesh>
          </geometry>
          <surface>
            <contact>
              <ode>
                <kp>1e+06</kp>
                <kd>1</kd>
              </ode>
            </contact>
            <friction>
              <ode>
                <mu>200</mu>
                <mu2>200</mu2>
              </ode>
              <torsional>
                <ode/>
              </torsional>
            </friction>
            <bounce/>
          </surface>
          <max_contacts>10</max_contacts>
        </collision>
        <visual name='back_wheel_right_visual'>
          <pose>0 0 0 0 -0 0</pose>
          <geometry>
            <mesh>
              <scale>1 1 1</scale>
              <uri>model://marvin_description/meshes/back_wheel_right.STL</uri>
            </mesh>
          </geometry>
          <material>
            <script>
              <name>Gazebo/Red</name>
              <uri>file://media/materials/scripts/gazebo.material</uri>
            </script>
          </material>
        </visual>
        <self_collide>0</self_collide>
        <enable_wind>0</enable_wind>
        <kinematic>0</kinematic>
      </link>
      <joint name='joint_front_wheel_left' type='revolute'>
        <pose relative_to='base_link'>0.13072 0.083994 -0.0215 0 -0 0</pose>
        <parent>base_link</parent>
        <child>front_wheel_left</child>
        <axis>
          <xyz>0 1 0</xyz>
          <limit>
            <effort>100</effort>
            <velocity>100</velocity>
            <lower>-1e+16</lower>
            <upper>1e+16</upper>
          </limit>
          <dynamics>
            <damping>0</damping>
            <friction>0.1</friction>
            <spring_reference>0</spring_reference>
            <spring_stiffness>0</spring_stiffness>
          </dynamics>
        </axis>
      </joint>
      <link name='front_wheel_left'>
        <pose relative_to='joint_front_wheel_left'>0 0 0 0 -0 0</pose>
        <inertial>
          <pose>0 -0.006483 0 0 -0 0</pose>
          <mass>0.063174</mass>
          <inertia>
            <ixx>3.6075e-05</ixx>
            <ixy>-7.3809e-21</ixy>
            <ixz>-3.1764e-22</ixz>
            <iyy>6.2912e-05</iyy>
            <iyz>3.9705e-21</iyz>
            <izz>3.6075e-05</izz>
          </inertia>
        </inertial>
        <collision name='front_wheel_left_collision'>
          <pose>0 0 0 0 -0 0</pose>
          <geometry>
            <mesh>
              <scale>1 1 1</scale>
              <uri>model://marvin_description/meshes/front_wheel_left.STL</uri>
            </mesh>
          </geometry>
          <surface>
            <contact>
              <ode>
                <kp>1e+06</kp>
                <kd>1</kd>
              </ode>
            </contact>
            <friction>
              <ode>
                <mu>200</mu>
                <mu2>200</mu2>
              </ode>
              <torsional>
                <ode/>
              </torsional>
            </friction>
            <bounce/>
          </surface>
          <max_contacts>10</max_contacts>
        </collision>
        <visual name='front_wheel_left_visual'>
          <pose>0 0 0 0 -0 0</pose>
          <geometry>
            <mesh>
              <scale>1 1 1</scale>
              <uri>model://marvin_description/meshes/front_wheel_left.STL</uri>
            </mesh>
          </geometry>
          <material>
            <script>
              <name>Gazebo/Red</name>
              <uri>file://media/materials/scripts/gazebo.material</uri>
            </script>
          </material>
        </visual>
        <self_collide>0</self_collide>
        <enable_wind>0</enable_wind>
        <kinematic>0</kinematic>
      </link>
      <joint name='joint_front_wheel_right' type='revolute'>
        <pose relative_to='base_link'>0.13072 -0.081976 -0.0215 0 -0 0</pose>
        <parent>base_link</parent>
        <child>front_wheel_right</child>
        <axis>
          <xyz>0 1 0</xyz>
          <limit>
            <effort>100</effort>
            <velocity>100</velocity>
            <lower>-1e+16</lower>
            <upper>1e+16</upper>
          </limit>
          <dynamics>
            <damping>0</damping>
            <friction>0.1</friction>
            <spring_reference>0</spring_reference>
            <spring_stiffness>0</spring_stiffness>
          </dynamics>
        </axis>
      </joint>
      <link name='front_wheel_right'>
        <pose relative_to='joint_front_wheel_right'>0 0 0 0 -0 0</pose>
        <inertial>
          <pose>0 0.006483 0 0 -0 0</pose>
          <mass>0.063174</mass>
          <inertia>
            <ixx>3.6075e-05</ixx>
            <ixy>-9.8931e-22</ixy>
            <ixz>-1.8794e-21</ixz>
            <iyy>6.2912e-05</iyy>
            <iyz>1.2176e-21</iyz>
            <izz>3.6075e-05</izz>
          </inertia>
        </inertial>
        <collision name='front_wheel_right_collision'>
          <pose>0 0 0 0 -0 0</pose>
          <geometry>
            <mesh>
              <scale>1 1 1</scale>
              <uri>model://marvin_description/meshes/front_wheel_right.STL</uri>
            </mesh>
          </geometry>
          <surface>
            <contact>
              <ode>
                <kp>1e+06</kp>
                <kd>1</kd>
              </ode>
            </contact>
            <friction>
              <ode>
                <mu>200</mu>
                <mu2>200</mu2>
              </ode>
              <torsional>
                <ode/>
              </torsional>
            </friction>
            <bounce/>
          </surface>
          <max_contacts>10</max_contacts>
        </collision>
        <visual name='front_wheel_right_visual'>
          <pose>0 0 0 0 -0 0</pose>
          <geometry>
            <mesh>
              <scale>1 1 1</scale>
              <uri>model://marvin_description/meshes/front_wheel_right.STL</uri>
            </mesh>
          </geometry>
          <material>
            <script>
              <name>Gazebo/Red</name>
              <uri>file://media/materials/scripts/gazebo.material</uri>
            </script>
          </material>
        </visual>
        <self_collide>0</self_collide>
        <enable_wind>0</enable_wind>
        <kinematic>0</kinematic>
      </link>
      <static>0</static>
      <plugin name='differential_drive_controller' filename='libgazebo_ros_diff_drive.so'>
        <ros>
          <remapping>odom:=odom/unfiltered</remapping>
        </ros>
        <updateRate>100</updateRate>
        <num_wheel_pairs>2</num_wheel_pairs>
        <left_joint>joint_back_wheel_left</left_joint>
        <left_joint>joint_front_wheel_left</left_joint>
        <right_joint>joint_back_wheel_right</right_joint>
        <right_joint>joint_front_wheel_right</right_joint>
        <wheel_separation>0.154</wheel_separation>
        <wheel_diameter>0.0635</wheel_diameter>
        <max_wheel_torque>2.4</max_wheel_torque>
        <max_wheel_acceleration>5.0</max_wheel_acceleration>
        <odometry_frame>odom</odometry_frame>
        <robot_base_frame>base_link</robot_base_frame>
        <publish_odom>1</publish_odom>
        <publish_odom_tf>1</publish_odom_tf>
        <publish_wheel_tf>1</publish_wheel_tf>
        <odometry_source>1</odometry_source>
      </plugin>
      <pose>-0.004612 5.1e-05 0.08 0 -0 0</pose>
    </model>
    <model name='Gas_Station'>
      <link name='link'>
        <pose>0 0 0 0 -0 0</pose>
        <self_collide>0</self_collide>
        <enable_wind>0</enable_wind>
        <kinematic>0</kinematic>
        <gravity>1</gravity>
        <inertial>
          <mass>1</mass>
          <pose>0 0 0 0 -0 0</pose>
          <inertia>
            <ixx>1</ixx>
            <ixy>0</ixy>
            <ixz>0</ixz>
            <iyy>1</iyy>
            <iyz>0</iyz>
            <izz>1</izz>
          </inertia>
        </inertial>
        <visual name='visual'>
          <geometry>
            <mesh>
              <uri>model://gas_station/meshes/gas_station.dae</uri>
              <scale>0.1 0.1 0.1</scale>
            </mesh>
          </geometry>
          <material>
            <script>
              <uri>model://gas_station/materials/scripts</uri>
              <uri>model://gas_station/materials/textures</uri>
              <name>GasStation/Diffuse</name>
            </script>
            <shader type='normal_map_tangent_space'>
              <normal_map>GasStation_Normal.png</normal_map>
            </shader>
            <ambient>1 1 1 1</ambient>
            <diffuse>1 1 1 1</diffuse>
            <specular>0 0 0 1</specular>
            <emissive>0 0 0 1</emissive>
          </material>
          <pose>0 0 0 0 -0 0</pose>
          <transparency>0</transparency>
          <cast_shadows>1</cast_shadows>
        </visual>
        <collision name='collision'>
          <laser_retro>0</laser_retro>
          <max_contacts>10</max_contacts>
          <pose>0 0 0 0 -0 0</pose>
          <geometry>
            <mesh>
              <uri>/home/marvin/.gazebo/models/gas_station/meshes/gas_station.dae</uri>
              <scale>1 1 1</scale>
            </mesh>
          </geometry>
          <surface>
            <friction>
              <ode>
                <mu>1</mu>
                <mu2>1</mu2>
                <fdir1>0 0 0</fdir1>
                <slip1>0</slip1>
                <slip2>0</slip2>
              </ode>
              <torsional>
                <coefficient>1</coefficient>
                <patch_radius>0</patch_radius>
                <surface_radius>0</surface_radius>
                <use_patch_radius>1</use_patch_radius>
                <ode>
                  <slip>0</slip>
                </ode>
              </torsional>
            </friction>
            <bounce>
              <restitution_coefficient>0</restitution_coefficient>
              <threshold>1e+06</threshold>
            </bounce>
            <contact>
              <collide_without_contact>0</collide_without_contact>
              <collide_without_contact_bitmask>1</collide_without_contact_bitmask>
              <collide_bitmask>1</collide_bitmask>
              <ode>
                <soft_cfm>0</soft_cfm>
                <soft_erp>0.2</soft_erp>
                <kp>1e+13</kp>
                <kd>1</kd>
                <max_vel>0.01</max_vel>
                <min_depth>0</min_depth>
              </ode>
              <bullet>
                <split_impulse>1</split_impulse>
                <split_impulse_penetration_threshold>-0.01</split_impulse_penetration_threshold>
                <soft_cfm>0</soft_cfm>
                <soft_erp>0.2</soft_erp>
                <kp>1e+13</kp>
                <kd>1</kd>
              </bullet>
            </contact>
          </surface>
        </collision>
      </link>
      <static>1</static>
      <allow_auto_disable>1</allow_auto_disable>
      <pose>0.389891 2.70973 0 0 -0 0</pose>
    </model>
  </world>
</sdf>
